fill ~-12 ~-3 ~12 ~-12 ~6 ~12 air 0 replace log2 0
fill ~-12 ~-3 ~12 ~-12 ~6 ~12 air 0 replace log 0
fill ~-12 ~-3 ~12 ~-12 ~6 ~12 air 0 replace leaves2 0
fill ~-12 ~-3 ~12 ~-12 ~6 ~12 air 0 replace leaves 0
fill ~-12 ~-3 ~12 ~-12 ~6 ~12 air 0 replace dirt 0
fill ~-12 ~-3 ~12 ~-12 ~6 ~12 air 0 replace grass 0
fill ~1 ~-3 ~5 ~1 ~55 ~5 sandstone 0
fill ~1 ~-3 ~6 ~1 ~-1 ~6 sandstone 0
fill ~1 ~-3 ~7 ~1 ~-1 ~7 sandstone 0
fill ~1 ~-3 ~8 ~1 ~55 ~8 sandstone 0
fill ~2 ~-3 ~3 ~2 ~55 ~3 sandstone 0
fill ~2 ~-3 ~4 ~2 ~55 ~4 sandstone 0
fill ~2 ~-3 ~9 ~2 ~55 ~9 sandstone 0
fill ~2 ~-3 ~10 ~2 ~55 ~10 sandstone 0
fill ~3 ~-3 ~1 ~3 ~55 ~1 sandstone 
fill ~3 ~-3 ~2 ~12 ~-3 ~2 sandstone 0
setblock ~3 ~-3 ~3 tallgrass 1
fill ~3 ~-3 ~11 ~3 ~55 ~11 sandstone 0
fill ~4 ~-3 ~0 ~11 ~-3 ~0 sandstone 0
fill ~4 ~-3 ~12 ~11 ~-3 ~12 sandstone 0
fill ~6 ~-3 ~13 ~9 ~-3 ~13 sandstone 0
setblock ~8 ~-3 ~1 tallgrass 1
setblock ~10 ~-3 ~1 sandstone_stairs 0
fill ~12 ~-3 ~1 ~12 ~55 ~1 sandstone 0
fill ~12 ~-3 ~11 ~12 ~55 ~11 sandstone 0
fill ~13 ~-3 ~3 ~13 ~55 ~3 sandstone 0
fill ~13 ~-3 ~4 ~13 ~55 ~4 sandstone 0
fill ~13 ~-3 ~9 ~13 ~55 ~9 sandstone 0
fill ~13 ~-3 ~10 ~13 ~55 ~10 sandstone 0
fill ~14 ~-3 ~5 ~14 ~55 ~5 sandstone 0
fill ~14 ~-3 ~6 ~14 ~-1 ~6 sandstone 0
fill ~14 ~-3 ~7 ~14 ~-1 ~7 sandstone 0
fill ~14 ~-3 ~8 ~14 ~55 ~8 sandstone 0
fill ~2 ~-2 ~5 ~13 ~-2 ~5 sandstone 0
fill ~2 ~-2 ~6 ~13 ~-2 ~6 sandstone 0
fill ~2 ~-2 ~7 ~13 ~-2 ~7 sandstone 0
fill ~2 ~-2 ~8 ~13 ~-2 ~8 sandstone 0
fill ~3 ~-2 ~2 ~3 ~55 ~2 sandstone 0
fill ~3 ~-2 ~3 ~12 ~-2 ~3 sandstone 0
fill ~3 ~-2 ~4 ~12 ~-2 ~4 sandstone 0
fill ~3 ~-2 ~9 ~12 ~-2 ~9 sandstone 0
fill ~3 ~-2 ~10 ~12 ~-2 ~10 sandstone 0
fill ~4 ~-2 ~0 ~11 ~-2 ~0 sandstone 0
fill ~4 ~-2 ~1 ~4 ~-2 ~11 sandstone 0
fill ~4 ~-2 ~12 ~5 ~-2 ~12 sandstone 0
fill ~5 ~-2 ~2 ~10 ~-2 ~2 sandstone 0
fill ~5 ~-2 ~11 ~11 ~-2 ~11 sandstone 0
fill ~6 ~-2 ~12 ~9 ~-2 ~12 sandstone 0
fill ~6 ~-2 ~13 ~9 ~-2 ~13 sandstone 0
fill ~10 ~-2 ~12 ~11 ~-2 ~12 sandstone 0
setblock ~11 ~-2 ~1 stone_stairs 0
setblock ~11 ~-2 ~2 double_stone_slab 0
fill ~12 ~-2 ~2 ~12 ~55 ~2 cobblestone 0
fill ~4 ~-1 ~0 ~11 ~-1 ~0 cobblestone 0
fill ~4 ~-1 ~12 ~11 ~-1 ~12 cobblestone 0
setblock ~5 ~-1 ~1 stone_stairs 0
fill ~5 ~-1 ~2 ~12 ~-1 ~2 cobblestone 0
setblock ~5 ~-1 ~9 mob_spawner 0
fill ~6 ~-1 ~13 ~9 ~-1 ~13 cobblestone 0
fill ~7 ~-1 ~10 ~8 ~-1 ~10 double_stone_slab 0
setblock ~10 ~-1 ~9 mob_spawner 0
fill ~4 ~0 ~0 ~11 ~0 ~0 cobblestone 0
fill ~4 ~0 ~12 ~11 ~0 ~12 cobblestone 0
fill ~5 ~0 ~2 ~12 ~0 ~2 cobblestone 0
setblock ~6 ~0 ~1 stone_stairs 0
fill ~6 ~0 ~13 ~9 ~0 ~13 cobblestone 0
fill ~7 ~0 ~10 ~8 ~0 ~10 chest 2
replaceitem block ~8 ~0 ~10 slot.container 1 apple 3
replaceitem block ~7 ~0 ~10 slot.container 8 iron_ingot 8
fill ~4 ~1 ~0 ~11 ~1 ~0 cobblestone 0
fill ~4 ~1 ~2 ~12 ~1 ~2 cobblestone 0
fill ~4 ~1 ~12 ~11 ~1 ~12 cobblestone 0
fill ~6 ~1 ~13 ~9 ~1 ~13 cobblestone 0
setblock ~7 ~1 ~1 stone_stairs 0
fill ~4 ~2 ~0 ~11 ~2 ~0 cobblestone 0
fill ~4 ~2 ~2 ~12 ~2 ~2 cobblestone 0
fill ~4 ~2 ~12 ~11 ~2 ~12 cobblestone 0
fill ~6 ~2 ~13 ~9 ~2 ~13 cobblestone 0
setblock ~8 ~2 ~1 stone_stairs 0
fill ~4 ~3 ~0 ~11 ~3 ~0 cobblestone 0
fill ~4 ~3 ~2 ~12 ~3 ~2 cobblestone 0
fill ~4 ~3 ~12 ~11 ~3 ~12 cobblestone 0
fill ~6 ~3 ~13 ~9 ~3 ~13 cobblestone 0
setblock ~9 ~3 ~1 stone_stairs 0
fill ~1 ~4 ~6 ~1 ~6 ~6 cobblestone 0
fill ~1 ~4 ~7 ~1 ~6 ~7 cobblestone 0
fill ~4 ~4 ~0 ~11 ~4 ~0 cobblestone 0
fill ~4 ~4 ~2 ~12 ~4 ~2 cobblestone 0
fill ~4 ~4 ~12 ~11 ~4 ~12 cobblestone 0
fill ~6 ~4 ~13 ~9 ~4 ~13 cobblestone 0
setblock ~10 ~4 ~1 stone_stairs 0
fill ~14 ~4 ~6 ~14 ~6 ~6 cobblestone 0
fill ~14 ~4 ~7 ~14 ~6 ~7 cobblestone 0
fill ~2 ~5 ~5 ~13 ~5 ~5 double_stone_slab 0
fill ~2 ~5 ~6 ~13 ~5 ~6 double_stone_slab 0
fill ~2 ~5 ~7 ~13 ~5 ~7 double_stone_slab 0
fill ~2 ~5 ~8 ~13 ~5 ~8 double_stone_slab 0
fill ~3 ~5 ~3 ~12 ~5 ~3 double_stone_slab 0
fill ~3 ~5 ~4 ~12 ~5 ~4 double_stone_slab 0
fill ~3 ~5 ~9 ~12 ~5 ~9 double_stone_slab 0
fill ~3 ~5 ~10 ~12 ~5 ~10 double_stone_slab 0
fill ~4 ~5 ~0 ~11 ~5 ~0 cobblestone 0
fill ~4 ~5 ~1 ~4 ~5 ~11 double_stone_slab 0
fill ~4 ~5 ~12 ~5 ~5 ~12 cobblestone 0
fill ~5 ~5 ~2 ~10 ~5 ~2 cobblestone 0
fill ~5 ~5 ~11 ~11 ~5 ~11 double_stone_slab 0
fill ~6 ~5 ~12 ~9 ~5 ~12 double_stone_slab 0
fill ~6 ~5 ~13 ~9 ~5 ~13 cobblestone 0
fill ~10 ~5 ~12 ~11 ~5 ~12 cobblestone 0
setblock ~11 ~5 ~1 stone_stairs 0
setblock ~11 ~5 ~2 double_stone_slab 0
fill ~4 ~6 ~0 ~11 ~6 ~0 cobblestone 0
fill ~4 ~6 ~12 ~11 ~6 ~12 cobblestone 0
setblock ~5 ~6 ~1 stone_stairs 0
fill ~5 ~6 ~2 ~10 ~6 ~2 cobblestone 0
setblock ~5 ~6 ~9 mob_spawner 0
fill ~6 ~6 ~13 ~9 ~6 ~13 cobblestone 0
fill ~7 ~6 ~10 ~8 ~6 ~10 double_stone_slab 0
setblock ~10 ~6 ~9 mob_spawner 0
fill ~4 ~7 ~0 ~11 ~7 ~0 cobblestone 0
fill ~4 ~7 ~12 ~11 ~7 ~12 cobblestone 0
fill ~5 ~7 ~2 ~10 ~7 ~2 cobblestone 0
setblock ~6 ~7 ~1 stone_stairs 0
fill ~6 ~7 ~13 ~9 ~7 ~13 cobblestone 0
fill ~7 ~7 ~10 ~8 ~7 ~10 chest 2
replaceitem block ~7 ~7 ~10 slot.container 4 rotten_flesh 14
replaceitem block ~8 ~7 ~10 slot.container 16 baked_potato 2
replaceitem block ~8 ~7 ~10 slot.container 10 arrow 29
fill ~4 ~8 ~0 ~11 ~8 ~0 cobblestone 0
fill ~4 ~8 ~2 ~12 ~8 ~2 cobblestone 0
fill ~4 ~8 ~12 ~11 ~8 ~12 cobblestone 0
fill ~6 ~8 ~13 ~9 ~8 ~13 cobblestone 0
setblock ~7 ~8 ~1 stone_stairs 0
fill ~4 ~9 ~0 ~11 ~9 ~0 cobblestone 0
fill ~4 ~9 ~2 ~12 ~9 ~2 cobblestone 0
fill ~4 ~9 ~12 ~11 ~9 ~12 cobblestone 0
fill ~6 ~9 ~13 ~9 ~9 ~13 cobblestone 0
setblock ~8 ~9 ~1 stone_stairs 0
fill ~4 ~10 ~0 ~11 ~10 ~0 cobblestone 0
fill ~4 ~10 ~2 ~12 ~10 ~2 cobblestone 0
fill ~4 ~10 ~12 ~11 ~10 ~12 cobblestone 0
fill ~6 ~10 ~13 ~9 ~10 ~13 cobblestone 0
setblock ~9 ~10 ~1 stone_stairs 0
fill ~1 ~11 ~6 ~1 ~13 ~6 cobblestone 0
fill ~1 ~11 ~7 ~1 ~13 ~7 cobblestone 0
fill ~4 ~11 ~0 ~11 ~11 ~0 cobblestone 0
fill ~4 ~11 ~2 ~12 ~11 ~2 cobblestone 0
fill ~4 ~11 ~12 ~11 ~11 ~12 cobblestone 0
fill ~6 ~11 ~13 ~9 ~11 ~13 cobblestone 0
setblock ~10 ~11 ~1 stone_stairs 0
fill ~14 ~11 ~6 ~14 ~13 ~6 cobblestone 0
fill ~14 ~11 ~7 ~14 ~13 ~7 cobblestone 0
fill ~2 ~12 ~5 ~13 ~12 ~5 double_stone_slab 0
fill ~2 ~12 ~6 ~8 ~12 ~6 double_stone_slab 0
fill ~2 ~12 ~7 ~13 ~12 ~7 double_stone_slab 0
fill ~2 ~12 ~8 ~13 ~12 ~8 double_stone_slab 0
fill ~3 ~12 ~3 ~12 ~12 ~3 double_stone_slab 0
fill ~3 ~12 ~4 ~12 ~12 ~4 double_stone_slab 0
fill ~3 ~12 ~9 ~12 ~12 ~9 double_stone_slab 0
fill ~3 ~12 ~10 ~12 ~12 ~10 double_stone_slab 0
fill ~4 ~12 ~0 ~11 ~12 ~0 cobblestone 0
fill ~4 ~12 ~1 ~4 ~12 ~11 double_stone_slab 0
fill ~4 ~12 ~12 ~5 ~12 ~12 cobblestone 0
fill ~5 ~12 ~2 ~10 ~12 ~2 cobblestone 0
fill ~5 ~12 ~11 ~11 ~12 ~11 double_stone_slab 0
fill ~6 ~12 ~12 ~9 ~12 ~12 double_stone_slab 0
fill ~6 ~12 ~13 ~9 ~12 ~13 cobblestone 0
fill ~10 ~12 ~6 ~13 ~12 ~6 double_stone_slab 0
fill ~10 ~12 ~12 ~11 ~12 ~12 cobblestone 0
setblock ~11 ~12 ~1 stone_stairs 0
setblock ~11 ~12 ~2 double_stone_slab 0
fill ~4 ~13 ~0 ~11 ~13 ~0 cobblestone 0
fill ~4 ~13 ~12 ~11 ~13 ~12 cobblestone 0
setblock ~5 ~13 ~1 stone_stairs 0
fill ~5 ~13 ~2 ~10 ~13 ~2 cobblestone 0
setblock ~5 ~13 ~9 mob_spawner 0
fill ~6 ~13 ~13 ~9 ~13 ~13 cobblestone 0
fill ~7 ~13 ~10 ~8 ~13 ~10 double_stone_slab 0
setblock ~10 ~13 ~9 mob_spawner 0
fill ~4 ~14 ~0 ~11 ~14 ~0 cobblestone 0
fill ~4 ~14 ~12 ~11 ~14 ~12 cobblestone 0
fill ~5 ~14 ~2 ~10 ~14 ~2 cobblestone 0
setblock ~6 ~14 ~1 stone_stairs 0
fill ~6 ~14 ~13 ~9 ~14 ~13 cobblestone 0
fill ~7 ~14 ~10 ~8 ~14 ~10 chest 2
replaceitem block ~7 ~14 ~10 slot.container 6 gold_ingot 12
replaceitem block ~7 ~14 ~10 slot.container 12 brick 20
replaceitem block ~8 ~14 ~10 slot.container 18 diamon 2
replaceitem block ~8 ~14 ~10 slot.container 2 beef 1
fill ~4 ~15 ~0 ~11 ~15 ~0 cobblestone 0
fill ~4 ~15 ~2 ~12 ~15 ~2 cobblestone 0
fill ~4 ~15 ~12 ~11 ~15 ~12 cobblestone 0
fill ~6 ~15 ~13 ~9 ~15 ~13 cobblestone 0
setblock ~7 ~15 ~1 stone_stairs 0
fill ~4 ~16 ~0 ~11 ~16 ~0 cobblestone 0
fill ~4 ~16 ~2 ~12 ~16 ~2 cobblestone 0
fill ~4 ~16 ~12 ~11 ~16 ~12 cobblestone 0
fill ~6 ~16 ~13 ~9 ~16 ~13 cobblestone 0
setblock ~8 ~16 ~1 stone_stairs 0
fill ~4 ~17 ~0 ~11 ~17 ~0 cobblestone 0
fill ~4 ~17 ~2 ~12 ~17 ~2 cobblestone 0
fill ~4 ~17 ~12 ~11 ~17 ~12 cobblestone 0
fill ~6 ~17 ~13 ~9 ~17 ~13 cobblestone 0
setblock ~9 ~17 ~1 stone_stairs 0
fill ~1 ~18 ~6 ~1 ~20 ~6 cobblestone 0
fill ~1 ~18 ~7 ~1 ~20 ~7 cobblestone 0
fill ~4 ~18 ~0 ~11 ~18 ~0 cobblestone 0
fill ~4 ~18 ~2 ~12 ~18 ~2 cobblestone 0
fill ~4 ~18 ~12 ~11 ~18 ~12 cobblestone 0
fill ~6 ~18 ~13 ~9 ~18 ~13 cobblestone 0
setblock ~10 ~18 ~1 stone_stairs 0
fill ~14 ~18 ~6 ~14 ~20 ~6 cobblestone 0
fill ~14 ~18 ~7 ~14 ~20 ~7 cobblestone 0
fill ~2 ~19 ~5 ~4 ~19 ~5 double_stone_slab 0
fill ~2 ~19 ~6 ~3 ~19 ~6 double_stone_slab 0
fill ~2 ~19 ~7 ~13 ~19 ~7 double_stone_slab 0
fill ~2 ~19 ~8 ~13 ~19 ~8 double_stone_slab 0
fill ~3 ~19 ~3 ~12 ~19 ~3 double_stone_slab 0
fill ~3 ~19 ~4 ~5 ~19 ~4 double_stone_slab 0
fill ~3 ~19 ~9 ~12 ~19 ~9 double_stone_slab 0
fill ~3 ~19 ~10 ~12 ~19 ~10 double_stone_slab 0
fill ~4 ~19 ~0 ~11 ~19 ~0 cobblestone 0
fill ~4 ~19 ~1 ~4 ~19 ~5 double_stone_slab 0
fill ~4 ~19 ~11 ~11 ~19 ~11 double_stone_slab 0
fill ~4 ~19 ~12 ~5 ~19 ~12 cobblestone 0
fill ~5 ~19 ~2 ~10 ~19 ~2 cobblestone 0
fill ~5 ~19 ~6 ~9 ~19 ~6 double_stone_slab 0
fill ~6 ~19 ~5 ~9 ~19 ~5 double_stone_slab 0
setblock ~6 ~19 ~12 double_stone_slab 0
fill ~6 ~19 ~13 ~9 ~19 ~13 cobblestone 0
fill ~7 ~19 ~4 ~12 ~19 ~4 double_stone_slab 0
fill ~8 ~19 ~12 ~9 ~19 ~12 double_stone_slab 0
fill ~10 ~19 ~12 ~11 ~19 ~12 cobblestone 0
setblock ~11 ~19 ~1 stone_stairs 0
setblock ~11 ~19 ~2 double_stone_slab 0
fill ~11 ~19 ~5 ~11 ~19 ~11 double_stone_slab 0
fill ~12 ~19 ~6 ~13 ~19 ~6 double_stone_slab 0
setblock ~13 ~19 ~5 double_stone_slab 0
fill ~4 ~20 ~0 ~11 ~20 ~0 cobblestone 0
fill ~4 ~20 ~12 ~11 ~20 ~12 cobblestone 0
setblock ~5 ~20 ~1 stone_stairs 0
fill ~5 ~20 ~2 ~10 ~20 ~2 cobblestone 0
setblock ~5 ~20 ~9 mob_spawner 0
fill ~6 ~20 ~13 ~9 ~20 ~13 cobblestone 0
fill ~7 ~20 ~10 ~8 ~20 ~10 double_stone_slab 0
setblock ~10 ~20 ~9 mob_spawner 0
fill ~4 ~21 ~0 ~11 ~21 ~0 cobblestone 0
fill ~4 ~21 ~12 ~11 ~21 ~12 cobblestone 0
fill ~5 ~21 ~2 ~10 ~21 ~2 cobblestone 0
setblock ~6 ~21 ~1 stone_stairs 0
fill ~6 ~21 ~13 ~9 ~21 ~13 cobblestone 0
fill ~7 ~21 ~10 ~8 ~21 ~10 chest 2
replaceitem block ~7 ~21 ~10 slot.container 10 gold_ingot 7
replaceitem block ~8 ~21 ~10 slot.container 11 iron_ingot 5
fill ~4 ~22 ~0 ~11 ~22 ~0 cobblestone 0
fill ~4 ~22 ~2 ~12 ~22 ~2 cobblestone 0
fill ~4 ~22 ~12 ~11 ~22 ~12 cobblestone 0
fill ~6 ~22 ~13 ~9 ~22 ~13 cobblestone 0
setblock ~7 ~22 ~1 stone_stairs 0
fill ~4 ~23 ~0 ~11 ~23 ~0 cobblestone 0
fill ~4 ~23 ~2 ~12 ~23 ~2 cobblestone 0
fill ~4 ~23 ~12 ~11 ~23 ~12 cobblestone 0
fill ~6 ~23 ~13 ~9 ~23 ~13 cobblestone 0
setblock ~8 ~23 ~1 stone_stairs 0
fill ~4 ~24 ~0 ~11 ~24 ~0 cobblestone 0
fill ~4 ~24 ~2 ~12 ~24 ~2 cobblestone 0
fill ~4 ~24 ~12 ~11 ~24 ~12 cobblestone 0
fill ~6 ~24 ~13 ~9 ~24 ~13 cobblestone 0
setblock ~9 ~24 ~1 stone_stairs 0
fill ~1 ~25 ~6 ~1 ~27 ~6 cobblestone 0
fill ~1 ~25 ~7 ~1 ~27 ~7 cobblestone 0
fill ~4 ~25 ~0 ~11 ~25 ~0 cobblestone 0
fill ~4 ~25 ~2 ~12 ~25 ~2 cobblestone 0
fill ~4 ~25 ~12 ~11 ~25 ~12 cobblestone 0
fill ~6 ~25 ~13 ~9 ~25 ~13 cobblestone 0
setblock ~10 ~25 ~1 stone_stairs 0
fill ~14 ~25 ~6 ~14 ~27 ~6 cobblestone 0
fill ~14 ~25 ~7 ~14 ~27 ~7 cobblestone 0
fill ~2 ~26 ~5 ~2 ~26 ~8 double_stone_slab 0
fill ~3 ~26 ~3 ~12 ~26 ~3 double_stone_slab 0
fill ~3 ~26 ~6 ~9 ~26 ~6 double_stone_slab 0
fill ~3 ~26 ~7 ~13 ~26 ~7 double_stone_slab 0
fill ~3 ~26 ~8 ~11 ~26 ~8 double_stone_slab 0
fill ~3 ~26 ~9 ~12 ~26 ~9 double_stone_slab 0
fill ~4 ~26 ~0 ~11 ~26 ~0 cobblestone 0
fill ~4 ~26 ~1 ~4 ~26 ~9 double_stone_slab 0
fill ~4 ~26 ~11 ~8 ~26 ~11 double_stone_slab 0
fill ~4 ~26 ~12 ~5 ~26 ~12 cobblestone 0
fill ~5 ~26 ~2 ~10 ~26 ~2 cobblestone 0
fill ~5 ~26 ~4 ~12 ~26 ~4 double_stone_slab 0
fill ~5 ~26 ~5 ~8 ~26 ~5 double_stone_slab 0
fill ~5 ~26 ~10 ~12 ~26 ~10 double_stone_slab 0
fill ~6 ~26 ~12 ~7 ~26 ~12 double_stone_slab 0
fill ~6 ~26 ~13 ~9 ~26 ~13 cobblestone 0
fill ~10 ~26 ~5 ~13 ~26 ~5 double_stone_slab 0
fill ~10 ~26 ~11 ~11 ~26 ~11 double_stone_slab 0
fill ~10 ~26 ~12 ~11 ~26 ~12 cobblestone 0
setblock ~11 ~26 ~1 stone_stairs 0
setblock ~11 ~26 ~2 double_stone_slab 0
fill ~11 ~26 ~6 ~13 ~26 ~6 double_stone_slab 0
setblock ~13 ~26 ~8 double_stone_slab 0
fill ~4 ~27 ~0 ~11 ~27 ~0 cobblestone 0
fill ~4 ~27 ~12 ~11 ~27 ~12 cobblestone 0
setblock ~5 ~27 ~1 stone_stairs 0
fill ~5 ~27 ~2 ~10 ~27 ~2 cobblestone 0
setblock ~5 ~27 ~9 mob_spawner 0
fill ~6 ~27 ~13 ~9 ~27 ~13 cobblestone 0
fill ~7 ~27 ~10 ~8 ~27 ~10 double_stone_slab 0
setblock ~10 ~27 ~9 mob_spawner 0
fill ~4 ~28 ~0 ~11 ~28 ~0 cobblestone 0
fill ~4 ~28 ~12 ~11 ~28 ~12 cobblestone 0
fill ~5 ~28 ~2 ~10 ~28 ~2 cobblestone 0
setblock ~6 ~28 ~1 stone_stairs 0
fill ~6 ~28 ~13 ~9 ~28 ~13 cobblestone 0
fill ~7 ~28 ~10 ~8 ~28 ~10 chest 2
replaceitem block ~7 ~28 ~10 slot.container 14 chicken 19
replaceitem block ~8 ~28 ~10 slot.container 16 bookshelf 8
replaceitem block ~7 ~28 ~10 slot.container 10 kelp 2
fill ~4 ~29 ~0 ~11 ~29 ~0 cobblestone 0
fill ~4 ~29 ~2 ~12 ~29 ~2 cobblestone 0
fill ~4 ~29 ~12 ~11 ~29 ~12 cobblestone 0
fill ~6 ~29 ~13 ~9 ~29 ~13 cobblestone 0
setblock ~7 ~29 ~1 stone_stairs 0
fill ~4 ~30 ~0 ~11 ~30 ~0 cobblestone 0
fill ~4 ~30 ~2 ~12 ~30 ~2 cobblestone 0
fill ~4 ~30 ~12 ~11 ~30 ~12 cobblestone 0
fill ~6 ~30 ~13 ~9 ~30 ~13 cobblestone 0
setblock ~8 ~30 ~1 stone_stairs 0
fill ~4 ~31 ~0 ~11 ~31 ~0 cobblestone 0
fill ~4 ~31 ~2 ~12 ~31 ~2 cobblestone 0
fill ~4 ~31 ~12 ~11 ~31 ~12 cobblestone 0
fill ~6 ~31 ~13 ~9 ~31 ~13 cobblestone 0
setblock ~9 ~31 ~1 stone_stairs 0
fill ~1 ~32 ~6 ~1 ~34 ~6 cobblestone 0
fill ~1 ~32 ~7 ~1 ~34 ~7 cobblestone 0
fill ~4 ~32 ~0 ~11 ~32 ~0 cobblestone 0
fill ~4 ~32 ~2 ~12 ~32 ~2 cobblestone 0
fill ~4 ~32 ~12 ~11 ~32 ~12 cobblestone 0
fill ~6 ~32 ~13 ~9 ~32 ~13 cobblestone 0
setblock ~10 ~32 ~1 stone_stairs 0
fill ~14 ~32 ~6 ~14 ~34 ~6 cobblestone 0
fill ~14 ~32 ~7 ~14 ~34 ~7 cobblestone 0
fill ~2 ~33 ~5 ~5 ~33 ~5 double_stone_slab 0
fill ~2 ~33 ~8 ~13 ~33 ~8 double_stone_slab 0
fill ~3 ~33 ~3 ~12 ~33 ~3 double_stone_slab 0
fill ~3 ~33 ~4 ~12 ~33 ~4 double_stone_slab 0
fill ~3 ~33 ~6 ~9 ~33 ~6 double_stone_slab 0
fill ~3 ~33 ~9 ~3 ~33 ~10 double_stone_slab 0
fill ~4 ~33 ~0 ~11 ~33 ~0 cobblestone 0
fill ~4 ~33 ~1 ~4 ~33 ~8 double_stone_slab 0
fill ~4 ~33 ~12 ~5 ~33 ~12 cobblestone 0
fill ~5 ~33 ~2 ~10 ~33 ~2 cobblestone 0
fill ~5 ~33 ~7 ~7 ~33 ~7 double_stone_slab 0
fill ~5 ~33 ~9 ~12 ~33 ~9 double_stone_slab 0
fill ~5 ~33 ~10 ~5 ~33 ~11 double_stone_slab 0
fill ~6 ~33 ~11 ~11 ~33 ~11 double_stone_slab 0
fill ~6 ~33 ~12 ~8 ~33 ~12 double_stone_slab 0
fill ~6 ~33 ~13 ~9 ~33 ~13 cobblestone 0
fill ~7 ~33 ~5 ~13 ~33 ~5 double_stone_slab 0
fill ~7 ~33 ~10 ~12 ~33 ~10 double_stone_slab 0
fill ~9 ~33 ~7 ~13 ~33 ~7 double_stone_slab 0
fill ~10 ~33 ~12 ~11 ~33 ~12 cobblestone 0
setblock ~11 ~33 ~1 stone_stairs 0
setblock ~11 ~33 ~2 double_stone_slab 0
fill ~11 ~33 ~6 ~13 ~33 ~6 double_stone_slab 0
fill ~4 ~34 ~0 ~11 ~34 ~0 cobblestone 0
fill ~4 ~34 ~12 ~11 ~34 ~12 cobblestone 0
setblock ~5 ~34 ~1 stone_stairs 0
fill ~5 ~34 ~2 ~10 ~34 ~2 cobblestone 0
setblock ~5 ~34 ~9 mob_spawner 0
fill ~6 ~34 ~13 ~9 ~34 ~13 cobblestone 0
fill ~7 ~34 ~10 ~8 ~34 ~10 double_stone_slab 0
setblock ~10 ~34 ~9 mob_spawner 0
fill ~4 ~35 ~0 ~11 ~35 ~0 cobblestone 0
fill ~4 ~35 ~12 ~11 ~35 ~12 cobblestone 0
fill ~5 ~35 ~2 ~10 ~35 ~2 cobblestone 0
setblock ~6 ~35 ~1 stone_stairs 0
fill ~6 ~35 ~13 ~9 ~35 ~13 cobblestone 0
fill ~7 ~35 ~10 ~8 ~35 ~10 chest 2
fill ~4 ~36 ~0 ~11 ~36 ~0 cobblestone 0
fill ~4 ~36 ~2 ~12 ~36 ~2 cobblestone 0
fill ~4 ~36 ~12 ~11 ~36 ~12 cobblestone 0
fill ~6 ~36 ~13 ~9 ~36 ~13 cobblestone 0
setblock ~7 ~36 ~1 stone_stairs 0
fill ~4 ~37 ~0 ~11 ~37 ~0 cobblestone 0
fill ~4 ~37 ~2 ~12 ~37 ~2 cobblestone 0
fill ~4 ~37 ~12 ~11 ~37 ~12 cobblestone 0
fill ~6 ~37 ~13 ~9 ~37 ~13 cobblestone 0
setblock ~8 ~37 ~1 stone_stairs 0
fill ~4 ~38 ~0 ~11 ~38 ~0 cobblestone 0
fill ~4 ~38 ~2 ~12 ~38 ~2 cobblestone 0
fill ~4 ~38 ~12 ~11 ~38 ~12 cobblestone 0
fill ~6 ~38 ~13 ~9 ~38 ~13 cobblestone 0
setblock ~9 ~38 ~1 stone_stairs 0
fill ~1 ~39 ~6 ~1 ~41 ~6 cobblestone 0
fill ~1 ~39 ~7 ~1 ~41 ~7 cobblestone 0
fill ~4 ~39 ~0 ~11 ~39 ~0 cobblestone 0
fill ~4 ~39 ~2 ~12 ~39 ~2 cobblestone 0
fill ~4 ~39 ~12 ~11 ~39 ~12 cobblestone 0
fill ~6 ~39 ~13 ~9 ~39 ~13 cobblestone 0
setblock ~10 ~39 ~1 stone_stairs 0
fill ~14 ~39 ~6 ~14 ~41 ~6 cobblestone 0
fill ~14 ~39 ~7 ~14 ~41 ~7 cobblestone 0
fill ~2 ~40 ~5 ~3 ~40 ~5 double_stone_slab 0
fill ~2 ~40 ~6 ~13 ~40 ~6 double_stone_slab 0
setblock ~2 ~40 ~8 double_stone_slab 0
fill ~3 ~40 ~3 ~12 ~40 ~3 double_stone_slab 0
fill ~3 ~40 ~4 ~5 ~40 ~4 double_stone_slab 0
fill ~3 ~40 ~7 ~4 ~40 ~7 double_stone_slab 0
fill ~3 ~40 ~10 ~5 ~40 ~10 double_stone_slab 0
fill ~4 ~40 ~0 ~11 ~40 ~0 cobblestone 0
fill ~4 ~40 ~1 ~4 ~40 ~4 double_stone_slab 0
fill ~4 ~40 ~9 ~6 ~40 ~9 double_stone_slab 0
fill ~4 ~40 ~11 ~5 ~40 ~11 double_stone_slab 0
fill ~4 ~40 ~12 ~5 ~40 ~12 cobblestone 0
fill ~5 ~40 ~2 ~10 ~40 ~2 cobblestone 0
fill ~5 ~40 ~5 ~6 ~40 ~5 double_stone_slab 0
fill ~6 ~40 ~7 ~9 ~40 ~7 double_stone_slab 0
fill ~6 ~40 ~12 ~9 ~40 ~12 double_stone_slab 0
fill ~6 ~40 ~13 ~9 ~40 ~13 cobblestone 0
fill ~7 ~40 ~4 ~12 ~40 ~4 double_stone_slab 0
fill ~7 ~40 ~8 ~13 ~40 ~8 double_stone_slab 0
fill ~7 ~40 ~10 ~8 ~40 ~10 double_stone_slab 0
fill ~7 ~40 ~11 ~7 ~40 ~10 double_stone_slab 0
setblock ~8 ~40 ~5 double_stone_slab 0
fill ~8 ~40 ~9 ~12 ~40 ~9 double_stone_slab 0
fill ~9 ~40 ~11 ~11 ~40 ~11 double_stone_slab 0
fill ~10 ~40 ~5 ~13 ~40 ~5 double_stone_slab 0
fill ~10 ~40 ~12 ~11 ~40 ~12 cobblestone 0
setblock ~11 ~40 ~1 stone_stairs 0
setblock ~11 ~40 ~2 double_stone_slab 0
fill ~11 ~40 ~7 ~13 ~40 ~7 double_stone_slab 0
fill ~11 ~40 ~10 ~12 ~40 ~10 double_stone_slab 0
fill ~4 ~41 ~0 ~11 ~41 ~0 cobblestone 0
fill ~4 ~41 ~12 ~11 ~41 ~12 cobblestone 0
setblock ~5 ~41 ~1 stone_stairs 0
fill ~5 ~41 ~2 ~10 ~41 ~2 cobblestone 0
setblock ~5 ~41 ~9 mob_spawner 0
fill ~6 ~41 ~13 ~9 ~41 ~13 cobblestone 0
fill ~7 ~41 ~10 ~8 ~41 ~10 double_stone_slab 0
setblock ~10 ~41 ~9 mob_spawner 0
fill ~4 ~42 ~0 ~11 ~42 ~0 cobblestone 0
fill ~4 ~42 ~12 ~11 ~42 ~12 cobblestone 0
fill ~5 ~42 ~2 ~10 ~42 ~2 cobblestone 0
setblock ~6 ~42 ~1 stone_stairs 0
summon zombie ~3.25488578189 ~-1.0 ~2.80000001192
summon zombie ~3.80000001192 ~-1.0 ~0.800000011921
summon zombie ~4.81389700199 ~0.0 ~1.04243077803
summon zombie ~5.49581256413 ~0.5 ~0.800000011921
summon skeleton ~6.30103894236 ~-1.0 ~5.70619413524
summon zombie ~6.12783006861 ~1.0 ~1.19999998808
summon zombie ~1.30909623368 ~7.0 ~6.01073722682
summon skeleton ~3.28355525591 ~-1.0 ~3.59577888132
summon skeleton ~4.11620092678 ~-1.0 ~5.95198605153
summon skeleton ~4.85269137752 ~-1.0 ~2.80000001192
summon skeleton ~4.00877680485 ~-1.0 ~2.54085253274
summon zombie ~4.19999998808 ~-1.0 ~1.61495639156
summon zombie ~5.25914020167 ~6.0 ~7.79752853573
summon skeleton ~4.69958231947 ~-1.0 ~10.215347798
summon creeper ~5.03335456656 ~-3.0 ~13.294013762
summon skeleton ~4.62744190347 ~-1.0 ~7.76004065057
summon skeleton ~2.32725090542 ~-1.0 ~7.37948985099
summon skeleton ~3.02853413466 ~-1.0 ~9.76569702266
summon skeleton ~7.29868181083 ~-1.0 ~6.92289835277
summon zombie ~5.31037759753 ~20.0 ~6.72012543414
summon zombie ~5.31037759753 ~24.0 ~6.72012543414
summon zombie ~5.31037759753 ~24.0 ~6.72012543414
summon zombie ~5.31037759753 ~25.0 ~6.72012543414
summon skeleton ~5.31037759753 ~28.0 ~6.72012543414
summon zombie ~5.31037759753 ~28.0 ~6.72012543414
summon zombie ~5.31037759753 ~28.0 ~6.72012543414
summon zombie ~5.31037759753 ~28.0 ~6.72012543414
summon skeleton ~5.31037759753 ~56.0 ~6.72012543414
summon zombie ~5.31037759753 ~56.0 ~6.72012543414
summon zombie ~5.31037759753 ~56.0 ~6.72012543414
summon skeleton ~5.31037759753 ~56.0 ~6.72012543414
summon zombie ~5.31037759753 ~42.0 ~6.72012543414
summon zombie ~5.31037759753 ~42.0 ~6.72012543414
summon zombie ~5.31037759753 ~42.0 ~6.72012543414
summon zombie ~5.31037759753 ~42.0 ~6.72012543414
summon skeleton ~5.31037759753 ~24.0 ~6.72012543414
summon zombie ~5.31037759753 ~42.0 ~6.72012543414
summon creeper ~8.79507407803 ~25 ~0.965246315286
summon creeper ~8.79507407803 ~45 ~0.965246315286
summon creeper ~8.79507407803 ~56 ~0.965246315286
summon creeper ~8.79507407803 ~14 ~0.965246315286
summon creeper ~8.79507407803 ~42 ~0.965246315286
summon skeleton ~10.700047913 ~-1.0 ~3.11724514198
summon skeleton ~12.6535132148 ~-1.0 ~5.92074198786
summon zombie ~11.8833478502 ~-1.0 ~5.99136662578
summon zombie ~10.6856118989 ~12.5 ~0.65000000596
summon zombie ~11.1999999881 ~13.0 ~0.800000011921
summon zombie ~10.2784637255 ~12.5 ~1.16486405259
summon zombie ~10.8507055122 ~13.0 ~1.45507774357
summon zombie ~9.67932771347 ~11.5 ~0.800000011921
summon zombie ~10.7245291194 ~20.0 ~1.00410920108
summon skeleton ~9.0136178309 ~-1.0 ~9.23407434985
summon zombie ~13.6890650854 ~7.0 ~6.994187323
summon zombie ~7.712987105 ~6.0 ~7.02155766482
summon zombie ~9.77881541674 ~6.0 ~11.0009064997
summon zombie ~8.24651880414 ~13.0 ~10.9627883871
summon zombie ~9.27046818388 ~13.0 ~10.9387819759
summon skeleton ~9.02033386719 ~20.0 ~9.14973277816
fill ~6 ~42 ~13 ~9 ~42 ~13 cobblestone 0
fill ~7 ~42 ~10 ~8 ~42 ~10 chest 2
replaceitem block ~7 ~42 ~10 slot.container 6 bone_block 2
replaceitem block ~8 ~42 ~10 slot.container 19 diamond 4
replaceitem block ~7 ~42 ~10 slot.container 10 cake 2
replaceitem block ~8 ~42 ~10 slot.container 11 cactus 20
fill ~4 ~43 ~0 ~11 ~43 ~0 cobblestone 0
fill ~4 ~43 ~2 ~12 ~43 ~2 cobblestone 0
fill ~4 ~43 ~12 ~11 ~43 ~12 cobblestone 0
fill ~6 ~43 ~13 ~9 ~43 ~13 cobblestone 0
setblock ~7 ~43 ~1 stone_stairs 0
fill ~4 ~44 ~0 ~11 ~44 ~0 cobblestone 0
fill ~4 ~44 ~2 ~12 ~44 ~2 cobblestone 0
fill ~4 ~44 ~12 ~11 ~44 ~12 cobblestone 0
fill ~6 ~44 ~13 ~9 ~44 ~13 cobblestone 0
setblock ~8 ~44 ~1 stone_stairs 0
fill ~4 ~45 ~0 ~11 ~45 ~0 cobblestone 0
fill ~4 ~45 ~2 ~12 ~45 ~2 cobblestone 0
fill ~4 ~45 ~12 ~11 ~45 ~12 cobblestone 0
fill ~6 ~45 ~13 ~9 ~45 ~13 cobblestone 0
setblock ~9 ~45 ~1 stone_stairs 0
fill ~1 ~46 ~6 ~1 ~48 ~6 cobblestone 0
fill ~1 ~46 ~7 ~1 ~48 ~7 cobblestone 0
fill ~4 ~46 ~0 ~11 ~46 ~0 cobblestone 0
fill ~4 ~46 ~2 ~12 ~46 ~2 cobblestone 0
fill ~4 ~46 ~12 ~11 ~46 ~12 cobblestone 0
fill ~6 ~46 ~13 ~9 ~46 ~13 cobblestone 0
setblock ~10 ~46 ~1 stone_stairs 0
fill ~14 ~46 ~6 ~14 ~48 ~6 cobblestone 0
fill ~14 ~46 ~7 ~14 ~48 ~7 cobblestone 0
fill ~2 ~47 ~5 ~11 ~47 ~5 double_stone_slab 0
fill ~2 ~47 ~6 ~5 ~47 ~6 double_stone_slab 0
fill ~2 ~47 ~7 ~8 ~47 ~7 double_stone_slab 0
fill ~3 ~47 ~3 ~12 ~47 ~3 double_stone_slab 0
fill ~3 ~47 ~4 ~12 ~47 ~4 double_stone_slab 0
fill ~3 ~47 ~8 ~9 ~47 ~8 double_stone_slab 0
fill ~3 ~47 ~9 ~7 ~47 ~9 double_stone_slab 0
fill ~3 ~47 ~10 ~4 ~47 ~10 double_stone_slab 0
fill ~4 ~47 ~0 ~11 ~47 ~0 cobblestone 0
fill ~4 ~47 ~1 ~4 ~47 ~11 double_stone_slab 0
fill ~4 ~47 ~12 ~5 ~47 ~12 cobblestone 0
fill ~5 ~47 ~2 ~10 ~47 ~2 cobblestone 0
fill ~5 ~47 ~11 ~10 ~47 ~11 double_stone_slab 0
setblock ~6 ~47 ~12 double_stone_slab 0
fill ~6 ~47 ~13 ~9 ~47 ~13 cobblestone 0
setblock ~7 ~47 ~6 double_stone_slab 0
fill ~7 ~47 ~10 ~12 ~47 ~10 double_stone_slab 0
fill ~8 ~47 ~12 ~9 ~47 ~12 double_stone_slab 0
setblock ~9 ~47 ~6 double_stone_slab 0
fill ~9 ~47 ~9 ~12 ~47 ~9 double_stone_slab 0
fill ~10 ~47 ~7 ~13 ~47 ~7 double_stone_slab 0
fill ~10 ~47 ~12 ~11 ~47 ~12 cobblestone 0
setblock ~11 ~47 ~1 stone_stairs 0
setblock ~11 ~47 ~2 double_stone_slab 0
setblock ~11 ~47 ~8 double_stone_slab 0
fill ~12 ~47 ~6 ~13 ~47 ~6 double_stone_slab 0
setblock ~13 ~47 ~8 double_stone_slab 0
fill ~4 ~48 ~0 ~11 ~48 ~0 cobblestone 0
fill ~4 ~48 ~12 ~11 ~48 ~12 cobblestone 0
setblock ~5 ~48 ~1 stone_stairs 0
fill ~5 ~48 ~2 ~10 ~48 ~2 cobblestone 0
setblock ~5 ~48 ~9 mob_spawner 0
fill ~6 ~48 ~13 ~9 ~48 ~13 cobblestone 0
fill ~7 ~48 ~10 ~8 ~48 ~10 double_stone_slab 0
setblock ~10 ~48 ~9 mob_spawner 0
fill ~4 ~49 ~0 ~11 ~49 ~0 cobblestone 0
fill ~4 ~49 ~12 ~11 ~49 ~12 cobblestone 0
fill ~5 ~49 ~2 ~10 ~49 ~2 cobblestone 0
setblock ~6 ~49 ~1 stone_stairs 0
fill ~6 ~49 ~13 ~9 ~49 ~13 cobblestone 0
fill ~7 ~49 ~10 ~8 ~49 ~10 chest 2
replaceitem block ~7 ~49 ~10 slot.container 1 lapis_block 1
replaceitem block ~7 ~49 ~10 slot.container 16 ladder 2
replaceitem block ~8 ~49 ~10 slot.container 17 sand 6
fill ~4 ~50 ~0 ~11 ~50 ~0 cobblestone 0
fill ~4 ~50 ~2 ~12 ~50 ~2 cobblestone 0
fill ~4 ~50 ~12 ~11 ~50 ~12 cobblestone 0
fill ~6 ~50 ~13 ~9 ~50 ~13 cobblestone 0
setblock ~7 ~50 ~1 stone_stairs 0
fill ~4 ~51 ~0 ~11 ~51 ~0 cobblestone 0
fill ~4 ~51 ~2 ~12 ~51 ~2 cobblestone 0
fill ~4 ~51 ~12 ~11 ~51 ~12 cobblestone 0
fill ~6 ~51 ~13 ~9 ~51 ~13 cobblestone 0
setblock ~8 ~51 ~1 stone_stairs 0
fill ~4 ~52 ~0 ~11 ~52 ~0 cobblestone 0
fill ~4 ~52 ~2 ~12 ~52 ~2 cobblestone 0
fill ~4 ~52 ~12 ~11 ~52 ~12 cobblestone 0
fill ~6 ~52 ~13 ~9 ~52 ~13 cobblestone 0
setblock ~9 ~52 ~1 stone_stairs 0
fill ~1 ~53 ~6 ~1 ~55 ~6 cobblestone 0
fill ~1 ~53 ~7 ~1 ~55 ~7 cobblestone 0
fill ~4 ~53 ~0 ~11 ~53 ~0 cobblestone 0
fill ~4 ~53 ~2 ~12 ~53 ~2 cobblestone 0
fill ~4 ~53 ~12 ~11 ~53 ~12 cobblestone 0
fill ~6 ~53 ~13 ~9 ~53 ~13 cobblestone 0
setblock ~10 ~53 ~1 stone_stairs 0
fill ~14 ~53 ~6 ~14 ~55 ~6 cobblestone 0
fill ~14 ~53 ~7 ~14 ~55 ~7 cobblestone 0
fill ~2 ~54 ~5 ~13 ~54 ~5 double_stone_slab 0
fill ~2 ~54 ~6 ~13 ~54 ~6 double_stone_slab 0
fill ~2 ~54 ~7 ~13 ~54 ~7 double_stone_slab 0
fill ~2 ~54 ~8 ~13 ~54 ~8 double_stone_slab 0
fill ~3 ~54 ~3 ~12 ~54 ~3 double_stone_slab 0
fill ~3 ~54 ~4 ~12 ~54 ~4 double_stone_slab 0
fill ~3 ~54 ~9 ~12 ~54 ~9 double_stone_slab 0
fill ~3 ~54 ~10 ~12 ~54 ~10 double_stone_slab 0
fill ~4 ~54 ~0 ~11 ~54 ~0 cobblestone 0
fill ~4 ~54 ~1 ~4 ~54 ~11 double_stone_slab 0
fill ~4 ~54 ~12 ~5 ~54 ~12 cobblestone 0
fill ~5 ~54 ~2 ~10 ~54 ~2 cobblestone 0
fill ~5 ~54 ~11 ~11 ~54 ~11 double_stone_slab 0
fill ~6 ~54 ~12 ~9 ~54 ~12 double_stone_slab 0
fill ~6 ~54 ~13 ~9 ~54 ~13 cobblestone 0
fill ~10 ~54 ~12 ~11 ~54 ~12 cobblestone 0
setblock ~11 ~54 ~1 stone_stairs 0
setblock ~11 ~54 ~2 double_stone_slab 0
fill ~4 ~55 ~0 ~11 ~55 ~0 cobblestone 0
fill ~4 ~55 ~12 ~11 ~55 ~12 cobblestone 0
fill ~5 ~55 ~1 ~5 ~55 ~2 cobblestone 0
fill ~6 ~55 ~2 ~10 ~55 ~2 cobblestone 0
fill ~6 ~55 ~13 ~9 ~55 ~13 cobblestone 0
fill ~7 ~55 ~10 ~8 ~55 ~10 double_stone_slab 0
fill ~7 ~56 ~10 ~8 ~56 ~10 chest 2
replaceitem block ~7 ~56 ~10 slot.container 11 gold_ingot 2
replaceitem block ~8 ~56 ~10 slot.container 10 iron_ingot 2
